<!-- 
  This URDF file is generated by simtrans, a robot model converter,
  and manually editted by Yuki Onishi (Tokyo Tech) for readability. -->

<robot name="sample_robot">
  <!-- Trunk -->
  <link name="HIPS">
    <inertial>
      <mass value="10.0"/>
      <origin xyz="0.0 0.0 0.0" rpy="0.0 0.0 0.0"/>
      <inertia ixx="0.04" ixy="0.0" ixz="0.0" iyy="0.04" iyz="0.0" izz="0.04"/>
    </inertial>
    <visual>
      <geometry>
        <mesh filename="package://choreonoid/ext/vnoid/model/sample_robot/Hips.stl"/>
      </geometry>
    </visual>
    <collision>
      <geometry>
        <mesh filename="package://choreonoid/ext/vnoid/model/sample_robot/Hips.stl"/>
      </geometry>
    </collision>
  </link>

  <joint name="CHEST_Y" type="revolute">
    <origin xyz="0.0 0.0 0.2" rpy="0.0 0.0 0.0"/>
    <axis xyz="0 0 1"/>
    <parent link="HIPS"/>
    <child link="CHEST_Y"/>
    <limit lower="-0.523598775598" upper="0.523598775598" effort="100.0" velocity="10"/>
  </joint>

  <link name="CHEST_Y">
    <inertial>
      <mass value="5.0"/>
      <origin xyz="0.0 0.0 0.0" rpy="0.0 0.0 0.0"/>
      <inertia ixx="0.02" ixy="0.0" ixz="0.0" iyy="0.02" iyz="0.0" izz="0.02"/>
    </inertial>
    <visual>
      <geometry>
        <mesh filename="package://choreonoid/ext/vnoid/model/sample_robot/ChestY.stl"/>
      </geometry>
    </visual>
    <collision>
      <geometry>
        <mesh filename="package://choreonoid/ext/vnoid/model/sample_robot/ChestY.stl"/>
      </geometry>
    </collision>
  </link>

  <joint name="CHEST_P" type="revolute">
    <origin xyz="0.0 0.0 0.0" rpy="0.0 0.0 0.0"/>
    <axis xyz="0 1 0"/>
    <parent link="CHEST_Y"/>
    <child link="CHEST_P"/>
    <limit lower="-0.523598775598" upper="1.2217304764" effort="100.0" velocity="10"/>
  </joint>

  <link name="CHEST_P">
    <inertial>
      <mass value="5.0"/>
      <origin xyz="0.0 0.0 0.0" rpy="0.0 0.0 0.0"/>
      <inertia ixx="0.02" ixy="0.0" ixz="0.0" iyy="0.02" iyz="0.0" izz="0.02"/>
    </inertial>
    <visual>
      <geometry>
        <mesh filename="package://choreonoid/ext/vnoid/model/sample_robot/ChestP.stl"/>
      </geometry>
    </visual>
    <collision>
      <geometry>
        <mesh filename="package://choreonoid/ext/vnoid/model/sample_robot/ChestP.stl"/>
      </geometry>
    </collision>
  </link>

  <!-- Head -->
  <joint name="HEAD_Y" type="revolute">
    <origin xyz="0.0 0.0 0.3" rpy="0.0 0.0 0.0"/>
    <axis xyz="0 0 1"/>
    <parent link="CHEST_P"/>
    <child link="HEAD_Y"/>
    <limit lower="-1.57079632679" upper="1.57079632679" effort="100.0" velocity="10"/>
  </joint>

  <link name="HEAD_Y">
    <inertial>
      <mass value="2.0"/>
      <origin xyz="0.0 0.0 0.0" rpy="0.0 0.0 0.0"/>
      <inertia ixx="0.01" ixy="0.0" ixz="0.0" iyy="0.01" iyz="0.0" izz="0.01"/>
    </inertial>
    <visual>
      <geometry>
        <mesh filename="package://choreonoid/ext/vnoid/model/sample_robot/HeadY.stl"/>
      </geometry>
    </visual>
    <collision>
      <geometry>
        <mesh filename="package://choreonoid/ext/vnoid/model/sample_robot/HeadY.stl"/>
      </geometry>
    </collision>
  </link>

  <joint name="HEAD_P" type="revolute">
    <origin xyz="0.0 0.0 0.0" rpy="0.0 0.0 0.0"/>
    <axis xyz="0 1 0"/>
    <parent link="HEAD_Y"/>
    <child link="HEAD_P"/>
    <limit lower="-0.523598775598" upper="1.0471975512" effort="100.0" velocity="10"/>
  </joint>

  <link name="HEAD_P">
    <inertial>
      <mass value="2.0"/>
      <origin xyz="0.0 0.0 0.0" rpy="0.0 0.0 0.0"/>
      <inertia ixx="0.01" ixy="0.0" ixz="0.0" iyy="0.01" iyz="0.0" izz="0.01"/>
    </inertial>
    <visual>
      <geometry>
        <mesh filename="package://choreonoid/ext/vnoid/model/sample_robot/HeadP.stl"/>
      </geometry>
    </visual>
    <collision>
      <geometry>
        <mesh filename="package://choreonoid/ext/vnoid/model/sample_robot/HeadP.stl"/>
      </geometry>
    </collision>
  </link>

  <!-- Right Arm -->
  <joint name="R_UPPERARM_P" type="revolute">
    <origin xyz="0.0 -0.1 0.1" rpy="0.0 0.0 0.0"/>
    <axis xyz="0 1 0"/>
    <parent link="CHEST_P"/>
    <child link="R_UPPERARM_P"/>
    <limit lower="-3.14159265359" upper="3.14159265359" effort="100.0" velocity="10"/>
  </joint>

  <link name="R_UPPERARM_P">
    <inertial>
      <mass value="0.5"/>
      <origin xyz="0.0 0.0 0.0" rpy="0.0 0.0 0.0"/>
      <inertia ixx="0.0004" ixy="0.0" ixz="0.0" iyy="0.0004" iyz="0.0" izz="0.0004"/>
    </inertial>
    <visual>
      <geometry>
        <mesh filename="package://choreonoid/ext/vnoid/model/sample_robot/UpperarmP.stl"/>
      </geometry>
    </visual>
    <collision>
      <geometry>
        <mesh filename="package://choreonoid/ext/vnoid/model/sample_robot/UpperarmP.stl"/>
      </geometry>
    </collision>
  </link>

  <joint name="R_UPPERARM_R" type="revolute">
    <origin xyz="0.0 0.0 0.0" rpy="0.0 0.0 0.0"/>
    <axis xyz="1 0 0"/>
    <parent link="R_UPPERARM_P"/>
    <child link="R_UPPERARM_R"/>
    <limit lower="-1.57079632679" upper="1.57079632679" effort="100.0" velocity="10"/>
  </joint>

  <link name="R_UPPERARM_R">
    <inertial>
      <mass value="0.5"/>
      <origin xyz="0.0 0.0 0.0" rpy="0.0 0.0 0.0"/>
      <inertia ixx="0.0004" ixy="0.0" ixz="0.0" iyy="0.0004" iyz="0.0" izz="0.0004"/>
    </inertial>
    <visual>
      <geometry>
        <mesh filename="package://choreonoid/ext/vnoid/model/sample_robot/UpperarmR.stl"/>
      </geometry>
    </visual>
    <collision>
      <geometry>
        <mesh filename="package://choreonoid/ext/vnoid/model/sample_robot/UpperarmR.stl"/>
      </geometry>
    </collision>
  </link>

  <joint name="R_UPPERARM_Y" type="revolute">
    <origin xyz="0.0 0.0 0.0" rpy="0.0 0.0 0.0"/>
    <axis xyz="0 0 1"/>
    <parent link="R_UPPERARM_R"/>
    <child link="R_UPPERARM_Y"/>
    <limit lower="-3.14159265359" upper="3.14159265359" effort="100.0" velocity="10"/>
  </joint>

  <link name="R_UPPERARM_Y">
    <inertial>
      <mass value="1.0"/>
      <origin xyz="0.0 0.0 -0.1" rpy="0.0 0.0 0.0"/>
      <inertia ixx="0.002" ixy="0.0" ixz="0.0" iyy="0.002" iyz="0.0" izz="0.0004"/>
    </inertial>
    <visual>
      <geometry>
        <mesh filename="package://choreonoid/ext/vnoid/model/sample_robot/UpperarmY.stl"/>
      </geometry>
    </visual>
    <collision>
      <geometry>
        <mesh filename="package://choreonoid/ext/vnoid/model/sample_robot/UpperarmY.stl"/>
      </geometry>
    </collision>
  </link>

  <joint name="R_LOWERARM_P" type="revolute">
    <origin xyz="0.0 0.0 -0.2" rpy="0.0 0.0 0.0"/>
    <axis xyz="0 1 0"/>
    <parent link="R_UPPERARM_Y"/>
    <child link="R_LOWERARM_P"/>
    <limit lower="-2.61799387799" upper="0.0" effort="100.0" velocity="10"/>
  </joint>

  <link name="R_LOWERARM_P">
    <inertial>
      <mass value="0.5"/>
      <origin xyz="0.0 0.0 0.0" rpy="0.0 0.0 0.0"/>
      <inertia ixx="0.0004" ixy="0.0" ixz="0.0" iyy="0.0004" iyz="0.0" izz="0.0004"/>
    </inertial>
    <visual>
      <geometry>
        <mesh filename="package://choreonoid/ext/vnoid/model/sample_robot/LowerarmP.stl"/>
      </geometry>
    </visual>
    <collision>
      <geometry>
        <mesh filename="package://choreonoid/ext/vnoid/model/sample_robot/LowerarmP.stl"/>
      </geometry>
    </collision>
  </link>

  <joint name="R_LOWERARM_Y" type="revolute">
    <origin xyz="0.0 0.0 0.0" rpy="0.0 0.0 0.0"/>
    <axis xyz="0 0 1"/>
    <parent link="R_LOWERARM_P"/>
    <child link="R_LOWERARM_Y"/>
    <limit lower="-1.57079632679" upper="1.57079632679" effort="100.0" velocity="10"/>
  </joint>

  <link name="R_LOWERARM_Y">
    <inertial>
      <mass value="1.0"/>
      <origin xyz="0.0 0.0 -0.1" rpy="0.0 0.0 0.0"/>
      <inertia ixx="0.002" ixy="0.0" ixz="0.0" iyy="0.002" iyz="0.0" izz="0.0004"/>
    </inertial>
    <visual>
      <geometry>
        <mesh filename="package://choreonoid/ext/vnoid/model/sample_robot/LowerarmY.stl"/>
      </geometry>
    </visual>
    <collision>
      <geometry>
        <mesh filename="package://choreonoid/ext/vnoid/model/sample_robot/LowerarmY.stl"/>
      </geometry>
    </collision>
  </link>

  <!-- Right Hand -->
  <joint name="R_HAND_P" type="revolute">
    <origin xyz="0.0 0.0 -0.2" rpy="0.0 0.0 0.0"/>
    <axis xyz="0 1 0"/>
    <parent link="R_LOWERARM_Y"/>
    <child link="R_HAND_P"/>
    <limit lower="-1.57079632679" upper="1.57079632679" effort="100.0" velocity="10"/>
  </joint>

  <link name="R_HAND_P">
    <inertial>
      <mass value="0.5"/>
      <origin xyz="0.0 0.0 0.0" rpy="0.0 0.0 0.0"/>
      <inertia ixx="0.0003" ixy="0.0" ixz="0.0" iyy="0.0003" iyz="0.0" izz="0.0003"/>
    </inertial>
    <visual>
      <geometry>
        <mesh filename="package://choreonoid/ext/vnoid/model/sample_robot/HandP.stl"/>
      </geometry>
    </visual>
    <collision>
      <geometry>
        <mesh filename="package://choreonoid/ext/vnoid/model/sample_robot/HandP.stl"/>
      </geometry>
    </collision>
  </link>

  <joint name="R_HAND_R" type="revolute">
    <origin xyz="0.0 0.0 0.0" rpy="0.0 0.0 0.0"/>
    <axis xyz="1 0 0"/>
    <parent link="R_HAND_P"/>
    <child link="R_HAND_R"/>
    <limit lower="-1.57079632679" upper="1.57079632679" effort="100.0" velocity="10"/>
  </joint>

  <link name="R_HAND_R">
    <inertial>
      <mass value="0.5"/>
      <origin xyz="0.0 0.0 0.0" rpy="0.0 0.0 0.0"/>
      <inertia ixx="0.0003" ixy="0.0" ixz="0.0" iyy="0.0003" iyz="0.0" izz="0.0003"/>
    </inertial>
    <visual>
      <geometry>
        <mesh filename="package://choreonoid/ext/vnoid/model/sample_robot/HandR.stl"/>
      </geometry>
    </visual>
    <collision>
      <geometry>
        <mesh filename="package://choreonoid/ext/vnoid/model/sample_robot/HandR.stl"/>
      </geometry>
    </collision>
  </link>

  <!-- Left Arm -->
  <joint name="L_UPPERARM_P" type="revolute">
    <origin xyz="0.0 0.1 0.1" rpy="0.0 0.0 0.0"/>
    <axis xyz="0 1 0"/>
    <parent link="CHEST_P"/>
    <child link="L_UPPERARM_P"/>
    <limit lower="-3.14159265359" upper="3.14159265359" effort="100.0" velocity="10"/>
  </joint>

  <link name="L_UPPERARM_P">
    <inertial>
      <mass value="0.5"/>
      <origin xyz="0.0 0.0 0.0" rpy="0.0 0.0 0.0"/>
      <inertia ixx="0.0004" ixy="0.0" ixz="0.0" iyy="0.0004" iyz="0.0" izz="0.0004"/>
    </inertial>
    <visual>
      <geometry>
        <mesh filename="package://choreonoid/ext/vnoid/model/sample_robot/UpperarmP.stl"/>
      </geometry>
    </visual>
    <collision>
      <geometry>
        <mesh filename="package://choreonoid/ext/vnoid/model/sample_robot/UpperarmP.stl"/>
      </geometry>
    </collision>
  </link>

  <joint name="L_UPPERARM_R" type="revolute">
    <origin xyz="0.0 0.0 0.0" rpy="0.0 0.0 0.0"/>
    <axis xyz="1 0 0"/>
    <parent link="L_UPPERARM_P"/>
    <child link="L_UPPERARM_R"/>
    <limit lower="-1.57079632679" upper="1.57079632679" effort="100.0" velocity="10"/>
  </joint>

  <link name="L_UPPERARM_R">
    <inertial>
      <mass value="0.5"/>
      <origin xyz="0.0 0.0 0.0" rpy="0.0 0.0 0.0"/>
      <inertia ixx="0.0004" ixy="0.0" ixz="0.0" iyy="0.0004" iyz="0.0" izz="0.0004"/>
    </inertial>
    <visual>
      <geometry>
        <mesh filename="package://choreonoid/ext/vnoid/model/sample_robot/UpperarmR.stl"/>
      </geometry>
    </visual>
    <collision>
      <geometry>
        <mesh filename="package://choreonoid/ext/vnoid/model/sample_robot/UpperarmR.stl"/>
      </geometry>
    </collision>
  </link>

  <joint name="L_UPPERARM_Y" type="revolute">
    <origin xyz="0.0 0.0 0.0" rpy="0.0 0.0 0.0"/>
    <axis xyz="0 0 1"/>
    <parent link="L_UPPERARM_R"/>
    <child link="L_UPPERARM_Y"/>
    <limit lower="-3.14159265359" upper="3.14159265359" effort="100.0" velocity="10"/>
  </joint>

  <link name="L_UPPERARM_Y">
    <inertial>
      <mass value="1.0"/>
      <origin xyz="0.0 0.0 -0.1" rpy="0.0 0.0 0.0"/>
      <inertia ixx="0.002" ixy="0.0" ixz="0.0" iyy="0.002" iyz="0.0" izz="0.0004"/>
    </inertial>
    <visual>
      <geometry>
        <mesh filename="package://choreonoid/ext/vnoid/model/sample_robot/UpperarmY.stl"/>
      </geometry>
    </visual>
    <collision>
      <geometry>
        <mesh filename="package://choreonoid/ext/vnoid/model/sample_robot/UpperarmY.stl"/>
      </geometry>
    </collision>
  </link>

  <joint name="L_LOWERARM_P" type="revolute">
    <origin xyz="0.0 -8.32667268469e-17 -0.2" rpy="0.0 0.0 0.0"/>
    <axis xyz="0 1 0"/>
    <parent link="L_UPPERARM_Y"/>
    <child link="L_LOWERARM_P"/>
    <limit lower="-2.61799387799" upper="0.0" effort="100.0" velocity="10"/>
  </joint>

  <link name="L_LOWERARM_P">
    <inertial>
      <mass value="0.5"/>
      <origin xyz="0.0 0.0 0.0" rpy="0.0 0.0 0.0"/>
      <inertia ixx="0.0004" ixy="0.0" ixz="0.0" iyy="0.0004" iyz="0.0" izz="0.0004"/>
    </inertial>
    <visual>
      <geometry>
        <mesh filename="package://choreonoid/ext/vnoid/model/sample_robot/LowerarmP.stl"/>
      </geometry>
    </visual>
    <collision>
      <geometry>
        <mesh filename="package://choreonoid/ext/vnoid/model/sample_robot/LowerarmP.stl"/>
      </geometry>
    </collision>
  </link>

  <joint name="L_LOWERARM_Y" type="revolute">
    <origin xyz="0.0 0.0 0.0" rpy="0.0 0.0 0.0"/>
    <axis xyz="0 0 1"/>
    <parent link="L_LOWERARM_P"/>
    <child link="L_LOWERARM_Y"/>
    <limit lower="-1.57079632679" upper="1.57079632679" effort="100.0" velocity="10"/>
  </joint>

  <link name="L_LOWERARM_Y">
    <inertial>
      <mass value="1.0"/>
      <origin xyz="0.0 0.0 -0.1" rpy="0.0 0.0 0.0"/>
      <inertia ixx="0.002" ixy="0.0" ixz="0.0" iyy="0.002" iyz="0.0" izz="0.0004"/>
    </inertial>
    <visual>
      <geometry>
        <mesh filename="package://choreonoid/ext/vnoid/model/sample_robot/LowerarmY.stl"/>
      </geometry>
    </visual>
    <collision>
      <geometry>
        <mesh filename="package://choreonoid/ext/vnoid/model/sample_robot/LowerarmY.stl"/>
      </geometry>
    </collision>
  </link>

  <!-- Left Hand -->
  <joint name="L_HAND_P" type="revolute">
    <origin xyz="0.0 0.0 -0.2" rpy="0.0 0.0 0.0"/>
    <axis xyz="0 1 0"/>
    <parent link="L_LOWERARM_Y"/>
    <child link="L_HAND_P"/>
    <limit lower="-1.57079632679" upper="1.57079632679" effort="100.0" velocity="10"/>
  </joint>

  <link name="L_HAND_P">
    <inertial>
      <mass value="0.5"/>
      <origin xyz="0.0 0.0 0.0" rpy="0.0 0.0 0.0"/>
      <inertia ixx="0.0003" ixy="0.0" ixz="0.0" iyy="0.0003" iyz="0.0" izz="0.0003"/>
    </inertial>
    <visual>
      <geometry>
        <mesh filename="package://choreonoid/ext/vnoid/model/sample_robot/HandP.stl"/>
      </geometry>
    </visual>
    <collision>
      <geometry>
        <mesh filename="package://choreonoid/ext/vnoid/model/sample_robot/HandP.stl"/>
      </geometry>
    </collision>
  </link>

  <joint name="L_HAND_R" type="revolute">
    <origin xyz="0.0 0.0 0.0" rpy="0.0 0.0 0.0"/>
    <axis xyz="1 0 0"/>
    <parent link="L_HAND_P"/>
    <child link="L_HAND_R"/>
    <limit lower="-1.57079632679" upper="1.57079632679" effort="100.0" velocity="10"/>
  </joint>

  <link name="L_HAND_R">
    <inertial>
      <mass value="0.5"/>
      <origin xyz="0.0 0.0 0.0" rpy="0.0 0.0 0.0"/>
      <inertia ixx="0.0003" ixy="0.0" ixz="0.0" iyy="0.0003" iyz="0.0" izz="0.0003"/>
    </inertial>
    <visual>
      <geometry>
        <mesh filename="package://choreonoid/ext/vnoid/model/sample_robot/HandR.stl"/>
      </geometry>
    </visual>
    <collision>
      <geometry>
        <mesh filename="package://choreonoid/ext/vnoid/model/sample_robot/HandR.stl"/>
      </geometry>
    </collision>
  </link>

  <!-- Right Leg -->
  <joint name="R_UPPERLEG_Y" type="revolute">
    <origin xyz="0.0 -0.1 -0.1" rpy="0.0 0.0 0.0"/>
    <axis xyz="0 0 1"/>
    <parent link="HIPS"/>
    <child link="R_UPPERLEG_Y"/>
    <limit lower="-3.14159265359" upper="3.14159265359" effort="100.0" velocity="10"/>
  </joint>

  <link name="R_UPPERLEG_Y">
    <inertial>
      <mass value="0.5"/>
      <origin xyz="0.0 0.0 0.0" rpy="0.0 0.0 0.0"/>
      <inertia ixx="0.0003" ixy="0.0" ixz="0.0" iyy="0.0003" iyz="0.0" izz="0.0003"/>
    </inertial>
    <visual>
      <geometry>
        <mesh filename="package://choreonoid/ext/vnoid/model/sample_robot/UpperlegY.stl"/>
      </geometry>
    </visual>
    <collision>
      <geometry>
        <mesh filename="package://choreonoid/ext/vnoid/model/sample_robot/UpperlegY.stl"/>
      </geometry>
    </collision>
  </link>

  <joint name="R_UPPERLEG_R" type="revolute">
    <origin xyz="0.0 0.0 0.0" rpy="0.0 0.0 0.0"/>
    <axis xyz="1 0 0"/>
    <parent link="R_UPPERLEG_Y"/>
    <child link="R_UPPERLEG_R"/>
    <limit lower="-0.523598775598" upper="0.523598775598" effort="100.0" velocity="10"/>
  </joint>

  <link name="R_UPPERLEG_R">
    <inertial>
      <mass value="0.5"/>
      <origin xyz="0.0 0.0 0.0" rpy="0.0 0.0 0.0"/>
      <inertia ixx="0.0003" ixy="0.0" ixz="0.0" iyy="0.0003" iyz="0.0" izz="0.0003"/>
    </inertial>
    <visual>
      <geometry>
        <mesh filename="package://choreonoid/ext/vnoid/model/sample_robot/UpperlegR.stl"/>
      </geometry>
    </visual>
    <collision>
      <geometry>
        <mesh filename="package://choreonoid/ext/vnoid/model/sample_robot/UpperlegR.stl"/>
      </geometry>
    </collision>
  </link>

  <joint name="R_UPPERLEG_P" type="revolute">
    <origin xyz="0.0 0.0 0.0" rpy="0.0 0.0 0.0"/>
    <axis xyz="0 1 0"/>
    <parent link="R_UPPERLEG_R"/>
    <child link="R_UPPERLEG_P"/>
    <limit lower="-1.91986217719" upper="0.523598775598" effort="100.0" velocity="10"/>
  </joint>

  <link name="R_UPPERLEG_P">
    <inertial>
      <mass value="1.5"/>
      <origin xyz="0.0 0.0 -0.15" rpy="0.0 0.0 0.0"/>
      <inertia ixx="0.01" ixy="0.0" ixz="0.0" iyy="0.01" iyz="0.0" izz="0.001"/>
    </inertial>
    <visual>
      <geometry>
        <mesh filename="package://choreonoid/ext/vnoid/model/sample_robot/UpperlegP.stl"/>
      </geometry>
    </visual>
    <collision>
      <geometry>
        <mesh filename="package://choreonoid/ext/vnoid/model/sample_robot/UpperlegP.stl"/>
      </geometry>
    </collision>
  </link>

  <joint name="R_LOWERLEG_P" type="revolute">
    <origin xyz="0.0 0.0 -0.3" rpy="0.0 0.0 0.0"/>
    <axis xyz="0 1 0"/>
    <parent link="R_UPPERLEG_P"/>
    <child link="R_LOWERLEG_P"/>
    <limit lower="0.0" upper="2.44346095279" effort="100.0" velocity="10"/>
  </joint>

  <link name="R_LOWERLEG_P">
    <inertial>
      <mass value="1.5"/>
      <origin xyz="0.0 0.0 -0.2" rpy="0.0 0.0 0.0"/>
      <inertia ixx="0.02" ixy="0.0" ixz="0.0" iyy="0.02" iyz="0.0" izz="0.002"/>
    </inertial>
    <visual>
      <geometry>
        <mesh filename="package://choreonoid/ext/vnoid/model/sample_robot/LowerlegP.stl"/>
      </geometry>
    </visual>
    <collision>
      <geometry>
        <mesh filename="package://choreonoid/ext/vnoid/model/sample_robot/LowerlegP.stl"/>
      </geometry>
    </collision>
  </link>

  <!-- Right Foot -->
  <joint name="R_FOOT_P" type="revolute">
    <origin xyz="0.0 0.0 -0.4" rpy="0.0 0.0 0.0"/>
    <axis xyz="0 1 0"/>
    <parent link="R_LOWERLEG_P"/>
    <child link="R_FOOT_P"/>
    <limit lower="-1.0471975512" upper="1.0471975512" effort="100.0" velocity="10"/>
  </joint>

  <link name="R_FOOT_P">
    <inertial>
      <mass value="0.5"/>
      <origin xyz="0.0 0.0 0.0" rpy="0.0 0.0 0.0"/>
      <inertia ixx="0.0003" ixy="0.0" ixz="0.0" iyy="0.0003" iyz="0.0" izz="0.0003"/>
    </inertial>
    <visual>
      <geometry>
        <mesh filename="package://choreonoid/ext/vnoid/model/sample_robot/FootP.stl"/>
      </geometry>
    </visual>
    <collision>
      <geometry>
        <mesh filename="package://choreonoid/ext/vnoid/model/sample_robot/FootP.stl"/>
      </geometry>
    </collision>
  </link>

  <joint name="R_FOOT_R" type="revolute">
    <origin xyz="0.0 0.0 0.0" rpy="0.0 0.0 0.0"/>
    <axis xyz="1 0 0"/>
    <parent link="R_FOOT_P"/>
    <child link="R_FOOT_R"/>
    <limit lower="-1.0471975512" upper="1.0471975512" effort="100.0" velocity="10"/>
  </joint>

  <link name="R_FOOT_R">
    <inertial>
      <mass value="0.5"/>
      <origin xyz="0.0 0.0 0.0" rpy="0.0 0.0 0.0"/>
      <inertia ixx="0.0003" ixy="0.0" ixz="0.0" iyy="0.001" iyz="0.0" izz="0.001"/>
    </inertial>
    <visual>
      <geometry>
        <mesh filename="package://choreonoid/ext/vnoid/model/sample_robot/FootR_flat.stl"/>
      </geometry>
    </visual>
    <collision>
      <geometry>
        <mesh filename="package://choreonoid/ext/vnoid/model/sample_robot/FootR_flat.stl"/>
      </geometry>
    </collision>
  </link>

  <!-- Left Leg -->
  <joint name="L_UPPERLEG_Y" type="revolute">
    <origin xyz="0.0 0.1 -0.1" rpy="0.0 0.0 0.0"/>
    <axis xyz="0 0 1"/>
    <parent link="HIPS"/>
    <child link="L_UPPERLEG_Y"/>
    <limit lower="-3.14159265359" upper="3.14159265359" effort="100.0" velocity="10"/>
  </joint>

  <link name="L_UPPERLEG_Y">
    <inertial>
      <mass value="0.5"/>
      <origin xyz="0.0 0.0 0.0" rpy="0.0 0.0 0.0"/>
      <inertia ixx="0.0003" ixy="0.0" ixz="0.0" iyy="0.0003" iyz="0.0" izz="0.0003"/>
    </inertial>
    <visual>
      <geometry>
        <mesh filename="package://choreonoid/ext/vnoid/model/sample_robot/UpperlegY.stl"/>
      </geometry>
    </visual>
    <collision>
      <geometry>
        <mesh filename="package://choreonoid/ext/vnoid/model/sample_robot/UpperlegY.stl"/>
      </geometry>
    </collision>
  </link>

  <joint name="L_UPPERLEG_R" type="revolute">
    <origin xyz="0.0 0.0 0.0" rpy="0.0 0.0 0.0"/>
    <axis xyz="1 0 0"/>
    <parent link="L_UPPERLEG_Y"/>
    <child link="L_UPPERLEG_R"/>
    <limit lower="-0.523598775598" upper="0.523598775598" effort="100.0" velocity="10"/>
  </joint>

  <link name="L_UPPERLEG_R">
    <inertial>
      <mass value="0.5"/>
      <origin xyz="0.0 0.0 0.0" rpy="0.0 0.0 0.0"/>
      <inertia ixx="0.0003" ixy="0.0" ixz="0.0" iyy="0.0003" iyz="0.0" izz="0.0003"/>
    </inertial>
    <visual>
      <geometry>
        <mesh filename="package://choreonoid/ext/vnoid/model/sample_robot/UpperlegR.stl"/>
      </geometry>
    </visual>
    <collision>
      <geometry>
        <mesh filename="package://choreonoid/ext/vnoid/model/sample_robot/UpperlegR.stl"/>
      </geometry>
    </collision>
  </link>

  <joint name="L_UPPERLEG_P" type="revolute">
    <origin xyz="0.0 0.0 0.0" rpy="0.0 0.0 0.0"/>
    <axis xyz="0 1 0"/>
    <parent link="L_UPPERLEG_R"/>
    <child link="L_UPPERLEG_P"/>
    <limit lower="-1.91986217719" upper="0.523598775598" effort="100.0" velocity="10"/>
  </joint>

  <link name="L_UPPERLEG_P">
    <inertial>
      <mass value="1.5"/>
      <origin xyz="0.0 0.0 -0.15" rpy="0.0 0.0 0.0"/>
      <inertia ixx="0.01" ixy="0.0" ixz="0.0" iyy="0.01" iyz="0.0" izz="0.001"/>
    </inertial>
    <visual>
      <geometry>
        <mesh filename="package://choreonoid/ext/vnoid/model/sample_robot/UpperlegP.stl"/>
      </geometry>
    </visual>
    <collision>
      <geometry>
        <mesh filename="package://choreonoid/ext/vnoid/model/sample_robot/UpperlegP.stl"/>
      </geometry>
    </collision>
  </link>

  <joint name="L_LOWERLEG_P" type="revolute">
    <origin xyz="0.0 0.0 -0.3" rpy="0.0 0.0 0.0"/>
    <axis xyz="0 1 0"/>
    <parent link="L_UPPERLEG_P"/>
    <child link="L_LOWERLEG_P"/>
    <limit lower="0.0" upper="2.44346095279" effort="100.0" velocity="10"/>
  </joint>

  <link name="L_LOWERLEG_P">
    <inertial>
      <mass value="1.5"/>
      <origin xyz="0.0 0.0 -0.2" rpy="0.0 0.0 0.0"/>
      <inertia ixx="0.02" ixy="0.0" ixz="0.0" iyy="0.02" iyz="0.0" izz="0.002"/>
    </inertial>
    <visual>
      <geometry>
        <mesh filename="package://choreonoid/ext/vnoid/model/sample_robot/LowerlegP.stl"/>
      </geometry>
    </visual>
    <collision>
      <geometry>
        <mesh filename="package://choreonoid/ext/vnoid/model/sample_robot/LowerlegP.stl"/>
      </geometry>
    </collision>
  </link>

  <!-- Left Hand -->
  <joint name="L_FOOT_P" type="revolute">
    <origin xyz="0.0 0.0 -0.4" rpy="0.0 0.0 0.0"/>
    <axis xyz="0 1 0"/>
    <parent link="L_LOWERLEG_P"/>
    <child link="L_FOOT_P"/>
    <limit lower="-1.0471975512" upper="1.0471975512" effort="100.0" velocity="10"/>
  </joint>

  <link name="L_FOOT_P">
    <inertial>
      <mass value="0.5"/>
      <origin xyz="0.0 0.0 0.0" rpy="0.0 0.0 0.0"/>
      <inertia ixx="0.0003" ixy="0.0" ixz="0.0" iyy="0.0003" iyz="0.0" izz="0.0003"/>
    </inertial>
    <visual>
      <geometry>
        <mesh filename="package://choreonoid/ext/vnoid/model/sample_robot/FootP.stl"/>
      </geometry>
    </visual>
    <collision>
      <geometry>
        <mesh filename="package://choreonoid/ext/vnoid/model/sample_robot/FootP.stl"/>
      </geometry>
    </collision>
  </link>

  <joint name="L_FOOT_R" type="revolute">
    <origin xyz="0.0 0.0 0.0" rpy="0.0 0.0 0.0"/>
    <axis xyz="1 0 0"/>
    <parent link="L_FOOT_P"/>
    <child link="L_FOOT_R"/>
    <limit lower="-1.0471975512" upper="1.0471975512" effort="100.0" velocity="10"/>
  </joint>

  <link name="L_FOOT_R">
    <inertial>
      <mass value="0.5"/>
      <origin xyz="0.0 0.0 0.0" rpy="0.0 0.0 0.0"/>
      <inertia ixx="0.0003" ixy="0.0" ixz="0.0" iyy="0.001" iyz="0.0" izz="0.001"/>
    </inertial>
    <visual>
      <geometry>
        <mesh filename="package://choreonoid/ext/vnoid/model/sample_robot/FootR_flat.stl"/>
      </geometry>
    </visual>
    <collision>
      <geometry>
        <mesh filename="package://choreonoid/ext/vnoid/model/sample_robot/FootR_flat.stl"/>
      </geometry>
    </collision>
  </link>

  <!-- Sensors -->
  <link name="bfsensor"/>
  <joint name="bfsensor_JOINT" type="fixed">
    <origin xyz="0.0 0.0 0.0" rpy="0.0 0.0 0.0"/>
    <parent link="HIPS"/>
    <child link="bfsensor"/>
  </joint>

  <link name="gyrometer"/>
  <joint name="gyrometer_JOINT" type="fixed">
    <origin xyz="0.0 0.0 0.0" rpy="0.0 0.0 0.0"/>
    <parent link="CHEST_Y"/>
    <child link="gyrometer"/>
  </joint>

  <link name="gsensor"/>
  <joint name="gsensor_JOINT" type="fixed">
    <origin xyz="0.0 0.0 0.0" rpy="0.0 0.0 0.0"/>
    <parent link="CHEST_Y"/>
    <child link="gsensor"/>
  </joint>

  <link name="rfsensor"/>
  <joint name="rfsensor_JOINT" type="fixed">
    <origin xyz="0.0 0.0 -0.05" rpy="0.0 0.0 0.0"/>
    <parent link="R_FOOT_R"/>
    <child link="rfsensor"/>
  </joint>

  <link name="lfsensor"/>
  <joint name="lfsensor_JOINT" type="fixed">
    <origin xyz="0.0 0.0 -0.05" rpy="0.0 0.0 0.0"/>
    <parent link="L_FOOT_R"/>
    <child link="lfsensor"/>
  </joint>
</robot>
